Workbook

Sheet PART I
B1: SPACE Matrix
A3: 1 | B3: Include five (and only five) factors to assess each SPACE axis: Financial Position (FP), Stability Position (SP), Competitive Position (CP), and Industry Position (IP).
A5: 2 | B5: Enter the five factors you wish to use each for FP, SP, CP, and IP and the corresponding rating each factor should receive. You may use the factors provided here, but try to determine key factors related to your company and industry in the same manner you did with the CPM. The calculations are done automatically and the rating scale is provided below.
A7: 3 | B7: Enter in the estimated FP, SP, CP, and IP numbers for up to two competitors. Or, instead of a competitor, you could show the estimated SPACE values for your firm after your proposed recommendations are implemented, ie a Before and After analysis. Or you could do both, just cut and paste the SPACE into PowerPoint then refill in the new data. It is important you fill in all information or Excel will place a circle(s) at the origin of the SPACE since the default will be (0,0) plot, which is the origin.
B9: FP and IP
B10: Positive 1 (worst) to Positive 7 (best)
B12: CP and SP
B13: Negative 1 (best) to Negative 7 (worst)
B15: Enter The Name Of Your Firm
D19: Ratings
B20: Financial Position (FP)
B21: Current Ratio
B22: Debt to Equity
B23: Net Income
B24: Revenue
B25: Inventory Turnover
B27: Industry Position (IP)
B28: Growth Potential
B29: Financial Stability
B30: Ease of Entry into Market
B31: Resource Utilization
B32: Profit Potential
D35: Ratings
B36: Competitive Position (CP)
B37: Market Share
B38: Product Quality
B39: Customer Loyalty
B40: Variety of Products Offered
B41: Control over Suppliers and Distributors
B43: Stability Position (SP)
B44: Rate of Inflation
B45: Technological Changes
B46: Price Elasticity of Demand
B47: Competitive Pressure
B48: Barriers to Entry into Market
B50: Your firm's X-axis | D50: =SUM(D28:D32)/5+SUM(D37:D41)/5 -> 0
B51: Your firm's Y-axis | D51: =SUM(D21:D25)/5+SUM(D44:D48)/5 -> 0
B55: Estimated FP
B56: Estimated IP
B57: Estimated CP
...

Sheet SPACE
B2: SPACE
A5: 1 | B5: If data is missing here, recheck the "Part I" page and read step 3.
A7: 2 | B7: Highlight the entire matrix (not just the inside box), and then paste as paste special picture. Be sure to also include the table below the chart also in your presentation.
A9: 3 | B9: If you do not see your bubble either you did not enter in the information or, it is also possible your bubble is behind another bubble if the X and Y information were close to the same.
M15: ='PART I'!B17 -> 0 | N15: ='PART I'!B53 -> 0 | O15: ='PART I'!B63 -> 0
L16: X Axis | M16: ='PART I'!D50 -> 0 | N16: ='PART I'!D60 -> 0 | O16: ='PART I'!D70 -> 0
L17: Y Axis | M17: ='PART I'!D51 -> 0 | N17: ='PART I'!D61 -> 0 | O17: ='PART I'!D71 -> 0
B29: Internal Analysis: | G29: External Analysis:
B30: Financial Position (FP) | G30: Stability Position (SP)
B31: ='PART I'!B21 -> Current Ratio | F31: ='PART I'!D21 -> 0 | G31: ='PART I'!B44 -> Rate of Inflation | K31: ='PART I'!D44 -> 0
B32: ='PART I'!B22 -> Debt to Equity | F32: ='PART I'!D22 -> 0 | G32: ='PART I'!B45 -> Technological Changes | K32: ='PART I'!D45 -> 0
B33: ='PART I'!B23 -> Net Income | F33: ='PART I'!D23 -> 0 | G33: ='PART I'!B46 -> Price Elasticity of Demand | K33: ='PART I'!D46 -> 0
B34: ='PART I'!B24 -> Revenue | F34: ='PART I'!D24 -> 0 | G34: ='PART I'!B47 -> Competitive Pressure | K34: ='PART I'!D47 -> 0
B35: ='PART I'!B25 -> Inventory Turnover | F35: ='PART I'!D25 -> 0 | G35: ='PART I'!B48 -> Barriers to Entry into Market | K35: ='PART I'!D48 -> 0
B36: Financial Position (FP) Average | F36: =SUM(F31:F35)/5 -> 0 | G36: Stability Position (SP) Average | K36: =SUM(K31:K35)/5 -> 0
B38: Internal Analysis: | G38: External Analysis:
B39: Competitive Position (CP) | G39: Industry Position (IP)
B40: ='PART I'!B37 -> Market Share | F40: ='PART I'!D37 -> 0 | G40: ='PART I'!B28 -> Growth Potential | K40: ='PART I'!D28 -> 0
B41: ='PART I'!B38 -> Product Quality | F41: ='PART I'!D38 -> 0 | G41: ='PART I'!B29 -> Financial Stability | K41: ='PART I'!D29 -> 0
B42: ='PART I'!B39 -> Customer Loyalty | F42: ='PART I'!D39 -> 0 | G42: ='PART I'!B30 -> Ease of Entry into Market | K42: ='PART I'!D30 -> 0
B43: ='PART I'!B40 -> Variety of Products Offered | F43: ='PART I'!D40 -> 0 | G43: ='PART I'!B31 -> Resource Utilization | K43: ='PART I'!D31 -> 0
B44: ='PART I'!B41 -> Control over Suppliers and Distributors | F44: ='PART I'!D41 -> 0 | G44: ='PART I'!B32 -> Profit Potential | K44: ='PART I'!D32 -> 0
B45: Competitive Position (CP) Average | F45: =SUM(F40:F44)/5 -> 0 | G45: Industry Position (IP) Average | K45: =SUM(K40:K44)/5 -> 0
